Workbook

Sheet Tests
A1: ID_Test | B1: Catégorie | C1: Exigence liée | D1: Fonctionnalité | E1: Description | F1: Mode | G1: Pré-requis | H1: Données entrée | I1: Résultat attendu | J1: Résultat obtenu | K1: Statut | L1: Sévérité | M1: Testeur | N1: Date | O1: Commentaires
A2: T-001 | B2: IHM | C2: REQ-IHM-01 | D2: Démarrage de l'application | E2: Démarrer l'application : 4 onglets principaux (📁/🔍/📜/⚙️) + barre d'état « Prêt » | F2: Manuel | G2: Exécutable compilé | H2: — | I2: Bandeau de 4 onglets, fenêtre 1200×800, panneau Organisation affiche lui-même 4 onglets internes (v2.3) | K2: À faire | L2: Bloquant
A3: T-002 | B3: IHM | C3: REQ-IHM-02 | D3: Navigation onglets | E3: Ctrl+1..4 navigue entre onglets, F1 ouvre À propos | F3: Manuel | G3: T-001 OK | H3: — | I3: Onglet actif change ; modale About s'ouvre | K3: À faire | L3: Majeur
A4: T-003 | B4: IHM | C4: REQ-IHM-03 | D4: Bouton thème ☀️/🌙 | E4: Clic bascule entre clair/sombre | F4: Manuel | G4: T-001 OK | H4: — | I4: Frames et boutons changent de couleur | K4: À faire | L4: Mineur
A5: T-004 | B5: IHM | C5: REQ-IHM-04 | D5: minsize fenêtre | E5: Réduire la fenêtre à 800×550 | F5: Manuel | G5: T-001 OK | H5: — | I5: Tous les boutons restent atteignables, scroll central activé si besoin | K5: À faire | L5: Majeur
A6: T-005 | B6: IHM | C6: REQ-IHM-05 | D6: Tooltips bouton Organiser | E6: Survoler 600 ms le bouton 🚀 Organiser | F6: Manuel | G6: T-001 OK | H6: — | I6: Info-bulle FR apparaît avec description action+effet | K6: À faire | L6: Mineur
A7: T-006 | B7: IHM | C7: REQ-IHM-06 | D7: Sticky bottom Organisation | E7: Fenêtre 1200×800 + déplier Avancé | F7: Manuel | G7: T-001 OK | H7: — | I7: Boutons d'action restent visibles, scroll central scrollable | K7: À faire | L7: Majeur
A8: T-007 | B8: IHM | C8: REQ-IHM-07 | D8: Onglet Filtrer accessible | E8: Cliquer l'onglet 🔍 Filtrer dans le bandeau d'onglets interne du panneau Organisation | F8: Manuel | G8: T-001 OK | H8: — | I8: Contenu Filtres visible, filtres date/taille/note/mots-clés accessibles (refonte v2.3 — remplace l'ancien bouton ▶ Avancé) | K8: À faire | L8: Majeur
A9: T-008 | B9: IHM | C9: REQ-IHM-08 | D9: Onglet Renommer accessible | E9: Cliquer l'onglet 🏷 Renommer dans le bandeau d'onglets interne du panneau Organisation | F9: Manuel | G9: T-001 OK | H9: — | I9: Contenu Renommer visible, exemples cliquables présents (refonte v2.3 — remplace l'ancien bouton Renommage repliable) | K9: À faire | L9: Mineur
A10: T-009 | B10: IHM | C10: REQ-IHM-09 | D10: Sidebar Doublons largeur ≥ 500 | E10: Onglet Doublons : vérif options non tronquées | F10: Manuel | G10: T-001 OK | H10: — | I10: Tous champs/cases lisibles sans scroll horizontal | K10: À faire | L10: Mineur
A11: T-010 | B11: IHM | C11: REQ-IHM-10 | D11: Compteur fichiers temps réel | E11: Sélectionner source nominal | F11: Manuel | G11: T-001 OK | H11: input_nominal/ | I11: Label « 📂 N fichier(s) prêt(s) » mis à jour < 2 s | K11: À faire | L11: Majeur
A12: T-011 | B12: IHM | C12: REQ-IHM-11 | D12: Sources multiples via + | E12: Cliquer + Source 2 fois sur 2 dossiers différents | F12: Manuel | G12: T-001 OK | H12: input_nominal/ + input_nominal_2/ | I12: Source field contient 'p1;p2', compteur cumule | K12: À faire | L12: Mineur
A13: T-012 | B13: IHM | C13: REQ-IHM-12 | D13: Drag & drop dossier | E13: Glisser un dossier depuis explorateur sur champ Source | F13: Manuel | G13: tkinterdnd2 OK | H13: input_nominal/ | I13: Champ Source mis à jour avec chemin | K13: À faire | L13: Mineur
... A51: T-050 | B51: Paramètres | C51: REQ-PRM-20 | D51: Récupération après configuration corrompue | E51: Modifier manuellement config.json (clé invalide) | F51: Manuel | G51: T-001 OK | H51: Configuration corrompue | I51: L'application démarre avec les valeurs par défaut + avertissement dans le journal | K51: À faire | L51: Majeur
A52: T-051 | B52: Entrées | C52: REQ-ENT-01 | D52: Cas nominal — 50 photos | E52: Lancer l'organisation sur le dossier nominal | F52: Auto | G52: T-001 OK | H52: input_nominal/ (50 .jpg) | I52: Tous traités : 50/50 fichiers traités, 0 erreur | J52: run_tests.py : 0 erreur ; références conformes | K52: OK | L52: Bloquant | M52: Claude (campagne auto) | N52: 2026-06-12
A53: T-052 | B53: Entrées | C53: REQ-ENT-02 | D53: input_vide | E53: Lancer organisation sur dossier vide | F53: Auto | G53: T-001 OK | H53: input_vide/ (0 fichier) | I53: Message 'Aucun fichier trouvé', 0 op | J53: run_tests.py : 0 erreur ; références conformes | K53: OK | L53: Majeur | M53: Claude (campagne auto) | N53: 2026-06-12
A54: T-053 | B54: Entrées | C54: REQ-ENT-03 | D54: input_volumineux 1000 photos | E54: Lancer organisation sur 1000 photos | F54: Auto | G54: T-001 OK | H54: input_volumineux/ (1000 .jpg) | I54: Pas de freeze IHM, progress 0→100%, < 60 s | J54: run_tests.py : 0 erreur ; références conformes | K54: OK | L54: Majeur | M54: Claude (campagne auto) | N54: 2026-06-12
A55: T-054 | B55: Entrées | C55: REQ-ENT-04 | D55: input_mauvais_format | E55: Source contient .txt, .pdf, .docx | F55: Manuel | G55: T-001 OK | H55: input_mauvais_format/ | I55: Filtrés par extensions, 0 photo traitée | K55: À faire | L55: Mineur
A56: T-055 | B56: Entrées | C56: REQ-ENT-05 | D56: input_caracteres_speciaux | E56: Noms avec accents, emojis, μ, Ω, ± | F56: Auto | G56: T-001 OK | H56: input_caracteres_speciaux/ | I56: Sanitization OK, pas de crash, noms valides | J56: run_tests.py : 0 erreur ; références conformes | K56: OK | L56: Majeur | M56: Claude (campagne auto) | N56: 2026-06-12
A57: T-056 | B57: Entrées | C57: REQ-ENT-06 | D57: Fichier JPG corrompu (tronqué) | E57: Photo JPG dont les 50 % derniers octets manquent | F57: Auto | G57: T-001 OK | H57: input_corrompu/ | I57: Ignoré avec avertissement dans le journal, 1 erreur, autres fichiers traités | J57: run_tests.py : 0 erreur ; références conformes | K57: OK | L57: Majeur | M57: Claude (campagne auto) | N57: 2026-06-12
A58: T-057 | B58: Entrées | C58: REQ-ENT-07 | D58: input_gps_piexif rationnels | E58: Photos avec EXIF GPS encodé piexif ((48,1)(51,1)(24,1)) | F58: Auto | G58: T-001 OK + GPS coché | H58: input_gps_piexif/ | I58: Coordonnées correctement extraites, organisées par lieu | J58: run_tests.py : 0 erreur ; références conformes | K58: OK | L58: Majeur | M58: Claude (campagne auto) | N58: 2026-06-12
A59: T-058 | B59: Entrées | C59: REQ-ENT-08 | D59: input_pairs RAW+JPEG | E59: 10 paires .CR2 + .JPG même stem | F59: Auto | G59: T-001 OK + keep_pairs ON | H59: input_pairs/ | I59: Pairs co-localisées dans même dossier dest | J59: run_tests.py : 0 erreur ; références conformes | K59: OK | L59: Mineur | M59: Claude (campagne auto) | N59: 2026-06-12
A60: T-059 | B60: Entrées | C60: REQ-ENT-09 | D60: input_bursts 5 photos < 3s | E60: 5 photos timestamps espacés de 1s | F60: Auto | G60: T-001 OK + detect_bursts ON | H60: input_bursts/ | I60: Sous-dossier Burst_01/ avec 5 fichiers | J60: run_tests.py : 0 erreur ; références conformes | K60: OK | L60: Mineur | M60: Claude (campagne auto) | N60: 2026-06-12
A61: T-060 | B61: Entrées | C61: REQ-ENT-10 | D61: input_pas_exif | E61: 3 photos sans aucune métadonnée EXIF | F61: Auto | G61: T-001 OK + date critère | H61: input_pas_exif/ | I61: Tous classés dans dossier 'Sans date' | J61: run_tests.py : 0 erreur ; références conformes | K61: OK | L61: Majeur | M61: Claude (campagne auto) | N61: 2026-06-12
A62: T-061 | B62: Entrées | C62: REQ-ENT-11 | D62: input_doublons 10 paires | E62: 20 photos dont 10 doublons exacts | F62: Manuel | G62: T-001 OK | H62: input_doublons/ | I62: DRY_RUN détecte 10 groupes de 2 | K62: À faire | L62: Bloquant
A63: T-062 | B63: Entrées | C63: REQ-ENT-12 | D63: input HEIC iPhone | E63: Photo HEIC avec EXIF | F63: Manuel | G63: pillow_heif installé | H63: input_heic/ | I63: Lue, organisée, métadonnées extraites | K63: À faire | L63: Majeur
A64: T-063 | B64: Entrées | C64: REQ-ENT-13 | D64: input vidéo MP4 avec date | E64: 1 vidéo MP4 avec CreationTime EXIF | F64: Manuel | G64: include_videos ON | H64: input_video/ | I64: Organisée par date comme une photo | K64: À faire | L64: Mineur
A65: T-064 | B65: Entrées | C65: REQ-ENT-14 | D65: input_limite_haute 100 Mo | E65: 1 fichier RAW de 100 Mo | F65: Manuel | G65: T-001 OK | H65: input_limite_haute/ | I65: Traité sans timeout, log temps de copie | K65: À faire | L65: Mineur
A66: T-065 | B66: Entrées | C66: REQ-ENT-15 | D66: input_limite_basse 1 Ko | E66: 1 photo de < 1 Ko (vignette) | F66: Manuel | G66: filter_size_min OFF | H66: input_limite_basse/ | I66: Traitée comme une photo normale | K66: À faire | L66: Cosmétique
A67: T-066 | B67: Sorties | C67: REQ-SOR-01 | D67: Arbo year/month/day | E67: Format date par défaut sur nominal | F67: Auto | G67: T-001 OK | H67: input_nominal/ | I67: Structure dest/YYYY/MM/YYYY_MM_DD/*.jpg | J67: run_tests.py : 0 erreur ; références conformes | K67: OK | L67: Bloquant | M67: Claude (campagne auto) | N67: 2026-06-12
A68: T-067 | B68: Sorties | C68: REQ-SOR-02 | D68: Arbo year/month | E68: Format year/month | F68: Manuel | G68: T-066 OK | H68: input_nominal/ | I68: Structure dest/YYYY/YYYY_MM/*.jpg | K68: À faire | L68: Mineur
A69: T-068 | B69: Sorties | C69: REQ-SOR-03 | D69: Arbo multilayer date+camera | E69: Date+Camera multilayer | F69: Auto | G69: T-014 OK | H69: input_nominal/ | I69: dest/YYYY/MM/.../CameraModel/*.jpg | J69: run_tests.py : 0 erreur ; références conformes | K69: OK | L69: Majeur | M69: Claude (campagne auto) | N69: 2026-06-12
A70: T-069 | B70: Sorties | C70: REQ-SOR-04 | D70: Index CSV généré | E70: Cocher Index CSV | F70: Auto | G70: T-001 OK | H70: input_nominal/ | I70: dest/_photoorganizer_index_*.csv, colonnes valides | J70: run_tests.py : 0 erreur ; références conformes | K70: OK | L70: Majeur | M70: Claude (campagne auto) | N70: 2026-06-12
A71: T-070 | B71: Sorties | C71: REQ-SOR-05 | D71: Index JSON valide | E71: Cocher Index JSON | F71: Auto | G71: T-001 OK | H71: input_nominal/ | I71: Fichier JSON valide ; nombre d'enregistrements == nombre de fichiers traités | J71: run_tests.py : 0 erreur ; références conformes | K71: OK | L71: Majeur | M71: Claude (campagne auto) | N71: 2026-06-12
A72: T-071 | B72: Sorties | C72: REQ-SOR-06 | D72: Rapport Doublons TXT | E72: Mode DRY_RUN + case TXT | F72: Manuel | G72: T-001 OK | H72: input_doublons/ | I72: duplicates_report_*.txt généré et lisible | K72: À faire | L72: Mineur
A73: T-072 | B73: Sorties | C73: REQ-SOR-07 | D73: Rapport Doublons CSV | E73: Mode DRY_RUN + case CSV | F73: Manuel | G73: T-001 OK | H73: input_doublons/ | I73: CSV exploitable Excel | K73: À faire | L73: Mineur
A74: T-073 | B74: Sorties | C74: REQ-SOR-08 | D74: Rapport Doublons JSON | E74: Mode DRY_RUN + case JSON | F74: Manuel | G74: T-001 OK | H74: input_doublons/ | I74: JSON structuré (groups, decisions, …) | K74: À faire | L74: Mineur
A75: T-074 | B75: Sorties | C75: REQ-SOR-09 | D75: Renommage template {date}_{counter} | E75: Template '{date:%Y%m%d}_{counter:04d}' | F75: Auto | G75: T-001 OK | H75: input_nominal/ | I75: Fichiers : 20260507_0001.jpg, 20260507_0002.jpg, … | J75: run_tests.py : 0 erreur ; références conformes | K75: OK | L75: Majeur | M75: Claude (campagne auto) | N75: 2026-06-12
A76: T-075 | B76: Sorties | C76: REQ-SOR-10 | D76: Renommage tokens manquants fallback | E76: Template avec {camera} sur photo sans EXIF | F76: Manuel | G76: T-001 OK | H76: input_pas_exif/ | I76: Fallback 'unknown' au lieu de crash | K76: À faire | L76: Mineur
A77: T-076 | B77: Sorties | C77: REQ-SOR-11 | D77: Burst sous-dossier Burst_NN | E77: detect_bursts ON, 5 photos < 3s | F77: Auto | G77: T-001 OK | H77: input_bursts/ | I77: Sous-dossier Burst_01/ contient les 5 | J77: run_tests.py : 0 erreur ; références conformes | K77: OK | L77: Mineur | M77: Claude (campagne auto) | N77: 2026-06-12
...

Sheet Synthèse
A1: Synthèse des tests — PhotoOrganizer 2.3.0.dev0 (campagne 2026-06-12 : pivot trial+unlock + audit lots A-F)
A3: Catégorie | B3: Total | C3: OK | D3: NOK | E3: NA | F3: À faire | G3: Taux OK (%)
A4: IHM | B4: =COUNTIF(Tests!B:B,A4) | C4: =COUNTIFS(Tests!B:B,A4,Tests!K:K,"OK") | D4: =COUNTIFS(Tests!B:B,A4,Tests!K:K,"NOK") | E4: =COUNTIFS(Tests!B:B,A4,Tests!K:K,"NA") | F4: =COUNTIFS(Tests!B:B,A4,Tests!K:K,"À faire") | G4: =IF(B4=0,"-",ROUND(C4/B4*100,1))
A5: Paramètres | B5: =COUNTIF(Tests!B:B,A5) | C5: =COUNTIFS(Tests!B:B,A5,Tests!K:K,"OK") | D5: =COUNTIFS(Tests!B:B,A5,Tests!K:K,"NOK") | E5: =COUNTIFS(Tests!B:B,A5,Tests!K:K,"NA") | F5: =COUNTIFS(Tests!B:B,A5,Tests!K:K,"À faire") | G5: =IF(B5=0,"-",ROUND(C5/B5*100,1))
A6: Entrées | B6: =COUNTIF(Tests!B:B,A6) | C6: =COUNTIFS(Tests!B:B,A6,Tests!K:K,"OK") | D6: =COUNTIFS(Tests!B:B,A6,Tests!K:K,"NOK") | E6: =COUNTIFS(Tests!B:B,A6,Tests!K:K,"NA") | F6: =COUNTIFS(Tests!B:B,A6,Tests!K:K,"À faire") | G6: =IF(B6=0,"-",ROUND(C6/B6*100,1))
A7: Sorties | B7: =COUNTIF(Tests!B:B,A7) | C7: =COUNTIFS(Tests!B:B,A7,Tests!K:K,"OK") | D7: =COUNTIFS(Tests!B:B,A7,Tests!K:K,"NOK") | E7: =COUNTIFS(Tests!B:B,A7,Tests!K:K,"NA") | F7: =COUNTIFS(Tests!B:B,A7,Tests!K:K,"À faire") | G7: =IF(B7=0,"-",ROUND(C7/B7*100,1))
A8: Cas limites | B8: =COUNTIF(Tests!B:B,A8) | C8: =COUNTIFS(Tests!B:B,A8,Tests!K:K,"OK") | D8: =COUNTIFS(Tests!B:B,A8,Tests!K:K,"NOK") | E8: =COUNTIFS(Tests!B:B,A8,Tests!K:K,"NA") | F8: =COUNTIFS(Tests!B:B,A8,Tests!K:K,"À faire") | G8: =IF(B8=0,"-",ROUND(C8/B8*100,1))
A9: Performance | B9: =COUNTIF(Tests!B:B,A9) | C9: =COUNTIFS(Tests!B:B,A9,Tests!K:K,"OK") | D9: =COUNTIFS(Tests!B:B,A9,Tests!K:K,"NOK") | E9: =COUNTIFS(Tests!B:B,A9,Tests!K:K,"NA") | F9: =COUNTIFS(Tests!B:B,A9,Tests!K:K,"À faire") | G9: =IF(B9=0,"-",ROUND(C9/B9*100,1))
A10: Robustesse | B10: =COUNTIF(Tests!B:B,A10) | C10: =COUNTIFS(Tests!B:B,A10,Tests!K:K,"OK") | D10: =COUNTIFS(Tests!B:B,A10,Tests!K:K,"NOK") | E10: =COUNTIFS(Tests!B:B,A10,Tests!K:K,"NA") | F10: =COUNTIFS(Tests!B:B,A10,Tests!K:K,"À faire") | G10: =IF(B10=0,"-",ROUND(C10/B10*100,1))
A11: Régression | B11: =COUNTIF(Tests!B:B,A11) | C11: =COUNTIFS(Tests!B:B,A11,Tests!K:K,"OK") | D11: =COUNTIFS(Tests!B:B,A11,Tests!K:K,"NOK") | E11: =COUNTIFS(Tests!B:B,A11,Tests!K:K,"NA") | F11: =COUNTIFS(Tests!B:B,A11,Tests!K:K,"À faire") | G11: =IF(B11=0,"-",ROUND(C11/B11*100,1))
A12: TOTAL | B12: =SUM(B4:B11) | C12: =SUM(C4:C11) | D12: =SUM(D4:D11) | E12: =SUM(E4:E11) | F12: =SUM(F4:F11) | G12: =IF(B12=0,"-",ROUND(C12/B12*100,1))
A15: Sévérité | B15: Total | C15: OK | D15: NOK
A16: Bloquant | B16: =COUNTIF(Tests!L:L,A16) | C16: =COUNTIFS(Tests!L:L,A16,Tests!K:K,"OK") | D16: =COUNTIFS(Tests!L:L,A16,Tests!K:K,"NOK")
A17: Majeur | B17: =COUNTIF(Tests!L:L,A17) | C17: =COUNTIFS(Tests!L:L,A17,Tests!K:K,"OK") | D17: =COUNTIFS(Tests!L:L,A17,Tests!K:K,"NOK")
A18: Mineur | B18: =COUNTIF(Tests!L:L,A18) | C18: =COUNTIFS(Tests!L:L,A18,Tests!K:K,"OK") | D18: =COUNTIFS(Tests!L:L,A18,Tests!K:K,"NOK")
A19: Cosmétique | B19: =COUNTIF(Tests!L:L,A19) | C19: =COUNTIFS(Tests!L:L,A19,Tests!K:K,"OK") | D19: =COUNTIFS(Tests!L:L,A19,Tests!K:K,"NOK")
A22: Mode | B22: Total | C22: OK | D22: NOK | E22: À faire | F22: Taux OK (%)
A23: Auto | B23: =COUNTIF(Tests!F:F,A23) | C23: =COUNTIFS(Tests!F:F,A23,Tests!K:K,"OK") | D23: =COUNTIFS(Tests!F:F,A23,Tests!K:K,"NOK") | E23: =COUNTIFS(Tests!F:F,A23,Tests!K:K,"À faire") | F23: =IF(B23=0,"-",ROUND(C23/B23*100,1))
A24: Manuel | B24: =COUNTIF(Tests!F:F,A24) | C24: =COUNTIFS(Tests!F:F,A24,Tests!K:K,"OK") | D24: =COUNTIFS(Tests!F:F,A24,Tests!K:K,"NOK") | E24: =COUNTIFS(Tests!F:F,A24,Tests!K:K,"À faire") | F24: =IF(B24=0,"-",ROUND(C24/B24*100,1))

Sheet Exigences
A1: Référentiel d'exigences fonctionnelles
A3: ID Exigence | B3: Catégorie | C3: Tests couvrants
A4: REQ-ENT-01 | B4: Entrées | C4: T-051
A5: REQ-ENT-02 | B5: Entrées | C5: T-052
A6: REQ-ENT-03 | B6: Entrées | C6: T-053
A7: REQ-ENT-04 | B7: Entrées | C7: T-054
A8: REQ-ENT-05 | B8: Entrées | C8: T-055
A9: REQ-ENT-06 | B9: Entrées | C9: T-056
A10: REQ-ENT-07 | B10: Entrées | C10: T-057
A11: REQ-ENT-08 | B11: Entrées | C11: T-058
A12: REQ-ENT-09 | B12: Entrées | C12: T-059
A13: REQ-ENT-10 | B13: Entrées | C13: T-060
A14: REQ-ENT-11 | B14: Entrées | C14: T-061
... A213: REQ-SOR-16 | B213: Sorties | C213: T-183

Sheet Légende
A1: Légende de la matrice
A3: Statut | B3: Description
A4: OK | B4: Test exécuté et conforme au résultat attendu
A5: NOK | B5: Test exécuté, résultat non conforme
A6: NA | B6: Non applicable (feature désactivée, dépendance absente, etc.)
A7: À faire | B7: Test pas encore exécuté (état initial)
A9: Sévérité | B9: Description
A10: Bloquant | B10: Empêche l'utilisation de la fonctionnalité ou de l'outil entier
A11: Majeur | B11: Dysfonctionnement important mais contournement possible
A12: Mineur | B12: Anomalie sans impact significatif sur l'usage
A13: Cosmétique | B13: Imperfection visuelle ou rédactionnelle
A15: Catégorie | B15: Périmètre
A16: IHM | B16: Comportement visuel et interactions widgets
... A27: Manuel | B27: Validation humaine via validation_ihm.html (rendu visuel, ergonomie, conditions réelles)
